Workbook

Sheet Summary
A1: ZOXIRO UNDERWRITING — DEAL SUMMARY
A2: Blank template — enter your deal inputs on the Assumptions and Scenarios tabs.
A4: Key Metric | B4: Property 1 | C4: Property 2 | D4: Combined
A5: PURCHASE
A6: Purchase Price | B6: =Assumptions!B6 | C6: =Assumptions!E6 | D6: =Assumptions!H6
A7: Units | B7: =Assumptions!B7 | C7: =Assumptions!E7 | D7: =Assumptions!H7
A8: Price Per Unit | B8: =Assumptions!B8 | C8: =Assumptions!E8 | D8: =Assumptions!H8
A9: Implied Going-In Cap Rate | B9: =Income_Statement!B22 | C9: =Income_Statement!C22 | D9: =Income_Statement!D22
A11: FINANCING STRUCTURE
A12: Senior DSCR Loan | B12: =Assumptions!B13 | C12: =Assumptions!E13 | D12: =B12+C12
A13: Seller Carry (2nd lien) | B13: =Assumptions!B20 | C13: =Assumptions!E20 | D13: =B13+C13
A14: Transactional Funding Needed | B14: =Assumptions!B31 | C14: =Assumptions!E31 | D14: =B14+C14
A15: Transactional Funding Cost (your funder's fee) | B15: =Assumptions!B33 | C15: =Assumptions!E33 | D15: =B15+C15
A16: Buyer Cash to Close | B16: =Assumptions!B27 | C16: =Assumptions!E27 | D16: =B16+C16
A18: INCOME & DEBT COVERAGE (Y1 Stabilized)
A19: Effective Gross Income (EGI) | B19: =Income_Statement!B8 | C19: =Income_Statement!C8 | D19: =Income_Statement!D8
A20: Net Operating Income (NOI) | B20: =Income_Statement!B21 | C20: =Income_Statement!C21 | D20: =Income_Statement!D21
A21: OpEx Ratio | B21: =Income_Statement!B18 | C21: =Income_Statement!C18 | D21: =Income_Statement!D18
A22: Total Debt Service (Sr + Carry) | B22: =Income_Statement!B27 | C22: =Income_Statement!C27 | D22: =Income_Statement!D27
A23: DSCR — Total Debt | B23: =Income_Statement!B29 | C23: =Income_Statement!C29 | D23: =Income_Statement!D29
A24: Annual Cash Flow After Debt Service | B24: =Income_Statement!B30 | C24: =Income_Statement!C30 | D24: =Income_Statement!D30
A25: Monthly Cash Flow | B25: =IFERROR(B24/12,"—") | C25: =IFERROR(C24/12,"—") | D25: =IFERROR(D24/12,"—")
A27: ="REFINANCE EXIT (Year "&Assumptions!B53&")"
A28: Stabilized Asset Value at Refi | B28: =Refi_Analysis!B10 | C28: =Refi_Analysis!C10 | D28: =Refi_Analysis!D10
A29: Max Refi Loan (Limiting) | B29: =Refi_Analysis!B20 | C29: =Refi_Analysis!C20 | D29: =Refi_Analysis!D20
A30: Stack Balance at Refi | B30: =Refi_Analysis!B26 | C30: =Refi_Analysis!C26 | D30: =Refi_Analysis!D26
A31: Refi Gap (Negative=Cash-Out) | B31: =Refi_Analysis!B28 | C31: =Refi_Analysis!C28 | D31: =Refi_Analysis!D28
A32: Refi Verdict | B32: =IF(Refi_Analysis!B28<=0,"PASS — CASH OUT",IF(Scenarios!B49>=Refi_Analysis!B28,"GAP COVERED BY BUYER CASH","NEEDS PLAN")) | C32: =IF(Refi_Analysis!C28<=0,"PASS — CASH OUT",IF(Scenarios!C49>=Refi_Analysis!C28,"GAP COVERED BY BUYER CASH","NEEDS PLAN")) | D32: =IF(Refi_Analysis!D28<=0,"PASS — CASH OUT",IF(Scenarios!D49>=Refi_Analysis!D28,"GAP COVERED BY BUYER CASH","NEEDS PLAN"))
A33: Earliest Clean Refi Year (solved) | B33: =IFERROR(Refi_Timeline!$C$29,"—") | C33: =IFERROR(Refi_Timeline!$C$29,"—") | D33: =IFERROR(Refi_Timeline!$C$29,"—")
A34: DEAL SCORE & VERDICT
A35: Deal Score (out of 100) | B35: =Deal_Score!C19 | C35: =Deal_Score!D19 | D35: =Deal_Score!E19
A36: Verdict | B36: =Deal_Score!C20 | C36: =Deal_Score!D20 | D36: =Deal_Score!E20
A37: Kill Flags Triggered | B37: =Kill_Flags!B15 | C37: =Kill_Flags!C15 | D37: =Kill_Flags!D15
A39: THE TWO GATES (added 1.14.38)
A40: Total Cash Invested | B40: =Income_Statement!B38 | C40: =Income_Statement!C38 | D40: =Income_Statement!D38
A41: Cash-on-Cash Return | B41: =Income_Statement!B39 | C41: =Income_Statement!C39 | D41: =Income_Statement!D39
A42: Gate — DSCR | B42: =Income_Statement!B40 | C42: =Income_Statement!C40 | D42: =Income_Statement!D40
A43: Gate — Cash-on-Cash | B43: =Income_Statement!B41 | C43: =Income_Statement!C41 | D43: =Income_Statement!D41
A44: Land deals → Land tab. Leasehold → Leasehold tab. Mixed NNN/gross centre → Recovery tab. Four offers on one property → Offers tab.
A46: WHY THIS MODEL IS BUILT THE WAY IT IS
...

Sheet Scenarios
A1: ZOXIRO — CAPITAL STRUCTURE SCENARIOS
A2: Blank template — enter your deal inputs on the Assumptions and Scenarios tabs.
B4: Property 1 | C4: Property 2 | D4: Combined
A5: PURCHASE TERMS (yellow = editable)
A6: Purchase Price ★ | D6: =B6+C6
A7: Units | D7: =B7+C7
A8: Price Per Unit | B8: =IFERROR(B6/B7,"—") | C8: =IFERROR(C6/C7,"—") | D8: =IFERROR(D6/D7,"—")
A10: INCOME — Y1 (Lender T12) vs STABILIZED (Y3, Market Rents)
A11: Y1 NOI (T12, incl. any day-one RUBS) ★ | D11: =B11+C11
A12: Stabilized NOI (Y3, market rents) ★ | D12: =B12+C12
A13: Going-In Cap (T12) | B13: =IFERROR(B11/B6,"—") | C13: =IFERROR(C11/C6,"—") | D13: =IFERROR(D11/D6,"—")
A14: Stabilized Cap | B14: =IFERROR(B12/B6,"—") | C14: =IFERROR(C12/C6,"—") | D14: =IFERROR(D12/D6,"—")
A16: FINANCING STRUCTURE — SOURCES OF FUNDS (yellow = editable)
A17: Senior LTV % ★ | B17: 0.65 | C17: 0.65 | D17: =IFERROR(AVERAGE(B17,C17),"—")
A18: Senior Loan | B18: =B6*B17 | C18: =C6*C17 | D18: =B18+C18
A19: Senior Rate ★ | B19: 0.075 | C19: 0.075 | D19: =IFERROR(AVERAGE(B19,C19),"—")
A20: Senior Term (yrs amort) ★ | B20: 30 | C20: 30 | D20: =IFERROR(AVERAGE(B20,C20),"—")
A21: Senior Annual DS | B21: =IFERROR(-PMT(B19/12,B20*12,B18)*12,"—") | C21: =IFERROR(-PMT(C19/12,C20*12,C18)*12,"—") | D21: =B21+C21
A22: Transactional Funding Gap % ★ | B22: 0.35 | C22: 0.35 | D22: =IFERROR(AVERAGE(B22,C22),"—")
A23: Transactional Funding $ (third party, same-day) | B23: =B6*B22 | C23: =C6*C22 | D23: =B23+C23
A24: Your Funder's Fee % ★ | B24: 0 | C24: 0 | D24: =IFERROR(AVERAGE(B24,C24),"—")
A25: Transactional Funding Cost $ | B25: =B23*B24 | C25: =C23*C24 | D25: =B25+C25
A26: Seller Carry % ★ | B26: 0.5 | C26: 0.5 | D26: =IFERROR(AVERAGE(B26,C26),"—")
A27: Seller Carry $ | B27: =B6*B26 | C27: =C6*C26 | D27: =B27+C27
A28: Carry Rate ★ | B28: 0 | C28: 0 | D28: =IFERROR(AVERAGE(B28,C28),"—")
A29: Carry Annual DS | B29: =B27*B28 | C29: =C27*C28 | D29: =B29+C29
A30: Balloon Term (yrs) ★ | B30: 10 | C30: 10 | D30: =IFERROR(AVERAGE(B30,C30),"—")
A31: TOTAL ANNUAL DS | B31: =B21+B29 | C31: =C21+C29 | D31: =B31+C31
A33: SOURCES & USES AT CLOSE — Where Every Dollar Moves
A34: SOURCES OF FUNDS:
A35: Senior DSCR Loan | B35: =B18 | C35: =C18 | D35: =D18
A36: Transactional Funding (third party, same-day) | B36: =B23 | C36: =C23 | D36: =D23
A37: TOTAL SOURCES (must = Purchase Price) | B37: =B35+B36 | C37: =C35+C36 | D37: =B37+C37
A38: Sources = Purchase Price? | B38: =IF(ROUND(B37-B6,0)=0,"✓ MATCH","✗ MISMATCH") | C38: =IF(ROUND(C37-C6,0)=0,"✓ MATCH","✗ MISMATCH") | D38: =IF(ROUND(D37-D6,0)=0,"✓ MATCH","✗ MISMATCH")
A40: USES OF FUNDS (where the cash flows):
A41: Cash to Seller (gross) | B41: =B6 | C41: =C6 | D41: =D6
A42: Less: Seller Carry-back to Buyer | B42: =-B27 | C42: =-C27 | D42: =-D27
A43: SELLER NET CASH AT CLOSE | B43: =B41+B42 | C43: =C41+C42 | D43: =D41+D42
A45: BUYER CASH POSITION AT CLOSE — Walk-Away Cash
A46: Carry-back (cash rebated to buyer) | B46: =B27 | C46: =C27 | D46: =D27
...

Sheet Market_Rents
A1: MARKET RENT ANALYSIS — COMP STUDY
A3: 3/1 COMPS — 1,000-1,300 SF, within 1 mile of subject
A4: Address | B4: Beds | C4: SF | D4: Rent | E4: $/SF | F4: Distance | G4: Days Listed | H4: Notes
E5: =IFERROR(D5/C5,"—")
E6: =IFERROR(D6/C6,"—")
E7: =IFERROR(D7/C7,"—")
E8: =IFERROR(D8/C8,"—")
E9: =IFERROR(D9/C9,"—")
E10: =IFERROR(D10/C10,"—")
E11: =IFERROR(D11/C11,"—")
E12: =IFERROR(D12/C12,"—")
A14: Median 3/1 Rent | D14: =IFERROR(MEDIAN(D5:D12),"—")
A15: Mean 3/1 Rent | D15: =IFERROR(AVERAGE(D5:D12),"—")
A16: Conservative 3/1 Underwrite | H16: Used in stabilized NOI calc
A19: 1/1 COMPS — within 1 mile
A20: Address | B20: Beds | C20: SF | D20: Rent | E20: $/SF | F20: Distance | G20: Days Listed | H20: Notes
E21: =IFERROR(D21/C21,"—")
E22: =IFERROR(D22/C22,"—")
E23: =IFERROR(D23/C23,"—")
E24: =IFERROR(D24/C24,"—")
A26: Median 1/1 Rent | D26: =IFERROR(MEDIAN(D21:D24),"—")
A27: Conservative 1/1 Underwrite | H27: Discount for older condition / no AC
A30: 2/1 COMPS — within 1 mile
A31: Address | B31: Beds | C31: SF | D31: Rent | E31: $/SF | F31: Distance | G31: Days Listed | H31: Notes
E32: =IFERROR(D32/C32,"—")
E33: =IFERROR(D33/C33,"—")
E34: =IFERROR(D34/C34,"—")
E35: =IFERROR(D35/C35,"—")
E36: =IFERROR(D36/C36,"—")
E37: =IFERROR(D37/C37,"—")
A39: Median 2/1 Rent | D39: =IFERROR(MEDIAN(D32:D37),"—")
A40: Conservative 2/1 Underwrite | H40: Anchored to a nearby comp (next door)
A43: LOSS-TO-LEASE — Subject vs. Market
A44: Building | B44: Unit | C44: Type | D44: Current $ | E44: Market $ | F44: Upside $/mo | G44: Annual Upside | H44: Lease Expires
F45: =E45-D45 | G45: =F45*12
F46: =E46-D46 | G46: =F46*12
F47: =E47-D47 | G47: =F47*12
F48: =E48-D48 | G48: =F48*12
F49: =E49-D49 | G49: =F49*12
F50: =E50-D50 | G50: =F50*12
...

Sheet Assumptions
A1: ZOXIRO UNDERWRITING — DEAL ASSUMPTIONS
A2: Blank template — enter your deal inputs on the Assumptions and Scenarios tabs.
A4: PURCHASE TERMS
B5: Property 1 | E5: Property 2 | H5: Combined
A6: Purchase Price | D6: Purchase Price | G6: Combined Purchase Price | H6: =B6+E6
A7: Units | D7: Units | G7: Total Units | H7: =B7+E7
A8: Price Per Unit | B8: =IFERROR(B6/B7,"—") | D8: Price Per Unit | E8: =IFERROR(E6/E7,"—") | G8: Combined PPU | H8: =IFERROR(H6/H7,"—")
A10: FINANCING STRUCTURE
B11: Property 1 | E11: Property 2
A12: Senior DSCR Loan LTV % | B12: 0.65 | D12: Senior DSCR Loan LTV % | E12: 0.65
A13: Senior Loan Amount | B13: =B6*B12 | D13: Senior Loan Amount | E13: =E6*E12
A14: Senior Loan Rate | B14: 0.075 | D14: Senior Loan Rate | E14: 0.075
A15: Senior Loan Term (yrs, amort) | B15: 30 | D15: Senior Loan Term (yrs, amort) | E15: 30
A16: Senior Loan IO Period (yrs) | B16: 0 | D16: Senior Loan IO Period (yrs) | E16: 0
A17: Senior Annual Debt Service | B17: =IFERROR(-PMT(B14/12,B15*12,B13)*12,"—") | D17: Senior Annual Debt Service | E17: =IFERROR(-PMT(E14/12,E15*12,E13)*12,"—")
A19: Seller Carry % | B19: 0.5 | D19: Seller Carry % | E19: 0.5
A20: Seller Carry Amount | B20: =B6*B19 | D20: Seller Carry Amount | E20: =E6*E19
A21: Seller Carry Rate | B21: 0 | D21: Seller Carry Rate | E21: 0
A22: Seller Carry Term (yrs, balloon) | B22: 10 | D22: Seller Carry Term (yrs, balloon) | E22: 10
A23: Seller Carry Pay Type (1=IO, 2=Amort, 3=Accrual) | B23: 1 | D23: Seller Carry Pay Type (1=IO, 2=Amort, 3=Accrual) | E23: 1
A24: Seller Carry Annual Debt Service | B24: =IFERROR(IF(B23=1,B20*B21,IF(B23=2,-PMT(B21/12,30*12,B20)*12,0)),"—") | E24: =IFERROR(IF(E23=1,E20*E21,IF(E23=2,-PMT(E21/12,30*12,E20)*12,0)),"—")
A26: TOTAL FINANCING (Sr + Carry) | B26: =B13+B20 | D26: TOTAL FINANCING (Sr + Carry) | E26: =E13+E20
A27: Cash Required to Close (before any transactional funding) | B27: =B6-B26 | D27: Cash to Close (before TF) | E27: =E6-E26
A28: Total Annual Debt Service | B28: =B17+B24 | D28: Total Annual Debt Service | E28: =E17+E24
A30: TRANSACTIONAL FUNDING (third party — enter your own funder's terms)
A31: Transactional Funding Needed | B31: =IFERROR(MAX(0,B27),"—") | D31: TF Required Amount (= Cash to Close) | E31: =IFERROR(MAX(0,E27),"—")
A32: Your Funder's Fee % | B32: 0 | D32: TF Fee % () | E32: 0
A33: Transactional Funding Cost $ | B33: =B31*B32 | D33: TF Fee $ (one-time, closing cost) | E33: =E31*E32
A35: INCOME ASSUMPTIONS
A36: Current Rent Roll (annualized GSI) | D36: Current Rent Roll (annualized GSI) | G36: Combined GSI | H36: =B36+E36
A37: Other Income (T12 actual) | D37: Other Income (T12 actual)
A38: Vacancy Allowance % | B38: 0.05 | D38: Vacancy Allowance % | E38: 0.05
A39: Vacancy $ | B39: =B36*B38 | D39: Vacancy $ | E39: =E36*E38
A40: EGI (Effective Gross Income) | B40: =B36+B37-B39 | D40: EGI (Effective Gross Income) | E40: =E36+E37-E39 | G40: Combined EGI | H40: =B40+E40
A41: Annual Rent Growth % | B41: 0.03 | D41: Annual Rent Growth % | E41: 0.03
A43: OPERATING EXPENSE ASSUMPTIONS (T12 NORMALIZED)
A44: Property Management % | B44: 0.1 | D44: Property Management % | E44: 0.1
A45: Property Tax (annual) | D45: Property Tax (annual)
A46: Property Insurance | D46: Property Insurance
A47: Utilities (owner-paid) | D47: Utilities (owner-paid)
...

Sheet Income_Statement
A1: INCOME STATEMENT — STABILIZED PRO FORMA (YEAR 1)
A3: Line Item | B3: Property 1 | C3: Property 2 | D3: Combined
A4: INCOME
A5: Gross Scheduled Income (GSI) | B5: =Assumptions!B36 | C5: =Assumptions!E36 | D5: =B5+C5
A6: Other Income | B6: =Assumptions!B37 | C6: =Assumptions!E37 | D6: =B6+C6
A7: Less: Vacancy | B7: =-Assumptions!B39 | C7: =-Assumptions!E39 | D7: =B7+C7
A8: Effective Gross Income (EGI) | B8: =B5+B6+B7 | C8: =C5+C6+C7 | D8: =B8+C8
A10: OPERATING EXPENSES
A11: Property Management | B11: =B8*Assumptions!B44 | C11: =C8*Assumptions!E44 | D11: =B11+C11
A12: Property Tax | B12: =Assumptions!B45 | C12: =Assumptions!E45 | D12: =B12+C12
A13: Property Insurance | B13: =Assumptions!B46 | C13: =Assumptions!E46 | D13: =B13+C13
A14: Utilities (owner-paid) | B14: =Assumptions!B47 | C14: =Assumptions!E47 | D14: =B14+C14
A15: Repairs & Maintenance | B15: =Assumptions!B48 | C15: =Assumptions!E48 | D15: =B15+C15
A16: Replacement Reserves | B16: =Assumptions!B49*Assumptions!B7 | C16: =Assumptions!E49*Assumptions!E7 | D16: =B16+C16
A17: Total Operating Expenses | B17: =SUM(B11:B16) | C17: =SUM(C11:C16) | D17: =B17+C17
A18: Operating Expense Ratio | B18: =IFERROR(B17/B8,"—") | C18: =IFERROR(C17/C8,"—") | D18: =IFERROR(D17/D8,"—")
A20: NET OPERATING INCOME
A21: NOI (Stabilized) | B21: =B8-B17 | C21: =C8-C17 | D21: =B21+C21
A22: Implied Cap Rate at Purchase Price | B22: =IFERROR(B21/Assumptions!B6,"—") | C22: =IFERROR(C21/Assumptions!E6,"—") | D22: =IFERROR(D21/Assumptions!H6,"—")
A24: DEBT SERVICE & DSCR
A25: Senior Loan Annual Debt Service | B25: =Assumptions!B17 | C25: =Assumptions!E17 | D25: =B25+C25
A26: Seller Carry Annual Debt Service | B26: =Assumptions!B24 | C26: =Assumptions!E24 | D26: =B26+C26
A27: Total Annual Debt Service | B27: =B25+B26 | C27: =C25+C26 | D27: =B27+C27
A28: DSCR — Senior Only | B28: =IFERROR(IF(B25=0,0,B21/B25),"—") | C28: =IFERROR(IF(C25=0,0,C21/C25),"—") | D28: =IFERROR(IF(D25=0,0,D21/D25),"—")
A29: DSCR — Total (Sr + Carry) | B29: =IFERROR(IF(B27=0,0,B21/B27),"—") | C29: =IFERROR(IF(C27=0,0,C21/C27),"—") | D29: =IFERROR(IF(D27=0,0,D21/D27),"—")
A30: Cash Flow After Total Debt Service | B30: =B21-B27 | C30: =C21-C27 | D30: =B30+C30
A32: CASH INVESTED & RETURN (added 1.14.38)
A33: Down payment actually paid (after transactional funding) | B33: =IFERROR(MAX(0,Assumptions!B27)-Assumptions!B31,0) | C33: =IFERROR(MAX(0,Assumptions!E27)-Assumptions!E31,0) | D33: =B33+C33
A34: Transactional funding fee | B34: =Assumptions!B33 | C34: =Assumptions!E33 | D34: =B34+C34
A35: Closing costs | B35: =Assumptions!B65 | C35: =Assumptions!E65 | D35: =B35+C35
A36: Prepaids & reserves | B36: =Assumptions!B66 | C36: =Assumptions!E66 | D36: =B36+C36
A37: Day-one capex | B37: =Assumptions!B67 | C37: =Assumptions!E67 | D37: =B37+C37
A38: TOTAL CASH INVESTED | B38: =IFERROR(SUM(B33:B37),"—") | C38: =IFERROR(SUM(C33:C37),"—") | D38: =IFERROR(SUM(D33:D37),"—")
A39: Cash-on-Cash Return | B39: =IFERROR(IF(B38<=0,"no cash in",B30/B38),"—") | C39: =IFERROR(IF(C38<=0,"no cash in",C30/C38),"—") | D39: =IFERROR(IF(D38<=0,"no cash in",D30/D38),"—")
A40: GATE — DSCR ≥ floor | B40: =IFERROR(IF(B27=0,"n/a — no debt",IF(B29>=Assumptions!$B$68,"PASS","FAIL")),"—") | C40: =IFERROR(IF(C27=0,"n/a — no debt",IF(C29>=Assumptions!$B$68,"PASS","FAIL")),"—") | D40: =IFERROR(IF(D27=0,"n/a — no debt",IF(D29>=Assumptions!$B$68,"PASS","FAIL")),"—")
A41: GATE — Cash-on-Cash ≥ floor | B41: =IFERROR(IF(NOT(ISNUMBER(B39)),"—",IF(B39>=Assumptions!$B$69,"PASS","FAIL")),"—") | C41: =IFERROR(IF(NOT(ISNUMBER(C39)),"—",IF(C39>=Assumptions!$B$69,"PASS","FAIL")),"—") | D41: =IFERROR(IF(NOT(ISNUMBER(D39)),"—",IF(D39>=Assumptions!$B$69,"PASS","FAIL")),"—")

Sheet Cash_Flow_10yr
A1: ZOXIRO — 10-YEAR CASH FLOW & STRESS TEST
A2: Combined Deal | Driven by Scenarios tab inputs | Stress tests show deal resilience under adverse conditions
A4: STRESS TEST INPUT KNOBS (yellow = editable — change to flex severity)
A5: NOI Growth Rate (annual, post-stab) | B5: 0.025 | C5: NOI growth is its own knob — deliberately separate from rent growth, because NOI nets expense inflation.
A6: Stabilization Year | B6: 3
A7: Stress: Rent Haircut % | B7: 0.05 | D7: (default 5% rent decline — moderate stress)
A8: Stress: OpEx Inflation % | B8: 0.08 | D8: (default 8% OpEx escalation — moderate stress)
A9: Stress: Refi Rate Add-On (bps) | B9: 0.01 | D9: (refi at 8% vs base 7%)
A10: Stress: Exit Cap Add-On (bps) | B10: 0.005 | D10: (exit cap 8.5% vs base 8%)
A11: Base Refi Rate | B11: =Assumptions!B56 | C11: Now reads the Assumptions tab.
A12: Base Exit Cap | B12: =Assumptions!B54 | C12: Now reads the Assumptions tab.
A14: SECTION 1 — BASE CASE 10-YEAR CASH FLOW PROJECTION (Combined Deal)
A15: Year | B15: Y1 | C15: Y2 | D15: Y3 | E15: Y4 | F15: Y5 | G15: Y6 | H15: Y7 | I15: Y8 | J15: Y9 | K15: Y10
A16: NOI | B16: =Scenarios!D11 | C16: =IFERROR(Scenarios!D11+(Scenarios!D12-Scenarios!D11)/2,"—") | D16: =Scenarios!D12 | E16: =Scenarios!D12*(1+B5)^(4-3) | F16: =Scenarios!D12*(1+B5)^(5-3) | G16: =Scenarios!D12*(1+B5)^(6-3) | H16: =Scenarios!D12*(1+B5)^(7-3) | I16: =Scenarios!D12*(1+B5)^(8-3) | J16: =Scenarios!D12*(1+B5)^(9-3) | K16: =Scenarios!D12*(1+B5)^(10-3)
A17: Senior DS (combined) | B17: =Scenarios!D21 | C17: =Scenarios!D21 | D17: =Scenarios!D21 | E17: =Scenarios!D21 | F17: =Scenarios!D21 | G17: =Scenarios!D21 | H17: =Scenarios!D21 | I17: =Scenarios!D21 | J17: =Scenarios!D21 | K17: =Scenarios!D21
A18: Carry DS (combined) | B18: =Scenarios!D29 | C18: =Scenarios!D29 | D18: =Scenarios!D29 | E18: =Scenarios!D29 | F18: =Scenarios!D29 | G18: =Scenarios!D29 | H18: =Scenarios!D29 | I18: =Scenarios!D29 | J18: =Scenarios!D29 | K18: =Scenarios!D29
A19: Total Debt Service | B19: =B17+B18 | C19: =C17+C18 | D19: =D17+D18 | E19: =E17+E18 | F19: =F17+F18 | G19: =G17+G18 | H19: =H17+H18 | I19: =I17+I18 | ... K19: =K17+K18
A20: DSCR (Total Debt) | B20: =IFERROR(B16/B19,"—") | C20: =IFERROR(C16/C19,"—") | D20: =IFERROR(D16/D19,"—") | E20: =IFERROR(E16/E19,"—") | F20: =IFERROR(F16/F19,"—") | G20: =IFERROR(G16/G19,"—") | H20: =IFERROR(H16/H19,"—") | I20: =IFERROR(I16/I19,"—") | ... K20: =IFERROR(K16/K19,"—")
A21: Annual CFAT | B21: =B16-B19 | C21: =C16-C19 | D21: =D16-D19 | E21: =E16-E19 | F21: =F16-F19 | G21: =G16-G19 | H21: =H16-H19 | I21: =I16-I19 | ... K21: =K16-K19
A22: Monthly CFAT | B22: =IFERROR(B21/12,"—") | C22: =IFERROR(C21/12,"—") | D22: =IFERROR(D21/12,"—") | E22: =IFERROR(E21/12,"—") | F22: =IFERROR(F21/12,"—") | G22: =IFERROR(G21/12,"—") | H22: =IFERROR(H21/12,"—") | I22: =IFERROR(I21/12,"—") | ... K22: =IFERROR(K21/12,"—")
A23: Cumulative CFAT | B23: =B21 | C23: =B23+C21 | D23: =C23+D21 | E23: =D23+E21 | F23: =E23+F21 | G23: =F23+G21 | H23: =G23+H21 | I23: =H23+I21 | J23: =I23+J21 | K23: =J23+K21
A24: ⚠️ HYPOTHETICAL SCENARIOS BELOW — NOT THE ACTUAL DEAL DSCR • Your real lender DSCR is on Row 20 • Stress tests show downside only
A25: SECTION 2 — STRESS TESTS (Hypothetical Adverse Scenarios — for internal underwriting, NOT lender DSCR)
A27: Stress A — Rent Haircut, per knob B7 (HYPOTHETICAL: vacancy spike or market softening)
A28: Revenue declines by the Rent Haircut % in B7. NOI = Base NOI - GSI × Rent Haircut.
A29: Year | B29: Y1 | C29: Y2 | D29: Y3 | E29: Y4 | F29: Y5 | G29: Y6 | H29: Y7 | I29: Y8 | J29: Y9 | K29: Y10
A30: Stressed NOI | B30: =IFERROR(B16-(Income_Statement!D5*(1+$B$5)^MAX(0,0)*$B$7),"—") | C30: =IFERROR(C16-(Income_Statement!D5*(1+$B$5)^MAX(0,1)*$B$7),"—") | D30: =IFERROR(D16-(Income_Statement!D5*(1+$B$5)^MAX(0,2)*$B$7),"—") | E30: =IFERROR(E16-(Income_Statement!D5*(1+$B$5)^MAX(0,3)*$B$7),"—") | F30: =IFERROR(F16-(Income_Statement!D5*(1+$B$5)^MAX(0,4)*$B$7),"—") | G30: =IFERROR(G16-(Income_Statement!D5*(1+$B$5)^MAX(0,5)*$B$7),"—") | H30: =IFERROR(H16-(Income_Statement!D5*(1+$B$5)^MAX(0,6)*$B$7),"—") | I30: =IFERROR(I16-(Income_Statement!D5*(1+$B$5)^MAX(0,7)*$B$7),"—") | J30: =IFERROR(J16-(Income_Statement!D5*(1+$B$5)^MAX(0,8)*$B$7),"—") | K30: =IFERROR(K16-(Income_Statement!D5*(1+$B$5)^MAX(0,9)*$B$7),"—")
A31: DSCR (Stressed) | B31: =IFERROR(B30/B19,"—") | C31: =IFERROR(C30/C19,"—") | D31: =IFERROR(D30/D19,"—") | E31: =IFERROR(E30/E19,"—") | F31: =IFERROR(F30/F19,"—") | G31: =IFERROR(G30/G19,"—") | H31: =IFERROR(H30/H19,"—") | I31: =IFERROR(I30/I19,"—") | ... K31: =IFERROR(K30/K19,"—")
A32: CFAT (Stressed) | B32: =B30-B19 | C32: =C30-C19 | D32: =D30-D19 | E32: =E30-E19 | F32: =F30-F19 | G32: =G30-G19 | H32: =H30-H19 | I32: =I30-I19 | ... K32: =K30-K19
A34: Stress B — OpEx Inflation, per knob B8 (HYPOTHETICAL: insurance hike, tax reassessment)
A35: OpEx escalates by the OpEx Inflation % in B8 (insurance hike, tax reassessment, maintenance surge). NOI loses OpEx × Inflation.
A36: Year | B36: Y1 | C36: Y2 | D36: Y3 | E36: Y4 | F36: Y5 | G36: Y6 | H36: Y7 | I36: Y8 | J36: Y9 | K36: Y10
A37: Stressed NOI | B37: =IFERROR(B16-(Income_Statement!D17*(1+Assumptions!$B$50)^MAX(0,0)*$B$8),"—") | C37: =IFERROR(C16-(Income_Statement!D17*(1+Assumptions!$B$50)^MAX(0,1)*$B$8),"—") | D37: =IFERROR(D16-(Income_Statement!D17*(1+Assumptions!$B$50)^MAX(0,2)*$B$8),"—") | E37: =IFERROR(E16-(Income_Statement!D17*(1+Assumptions!$B$50)^MAX(0,3)*$B$8),"—") | F37: =IFERROR(F16-(Income_Statement!D17*(1+Assumptions!$B$50)^MAX(0,4)*$B$8),"—") | G37: =IFERROR(G16-(Income_Statement!D17*(1+Assumptions!$B$50)^MAX(0,5)*$B$8),"—") | H37: =IFERROR(H16-(Income_Statement!D17*(1+Assumptions!$B$50)^MAX(0,6)*$B$8),"—") | I37: =IFERROR(I16-(Income_Statement!D17*(1+Assumptions!$B$50)^MAX(0,7)*$B$8),"—") | J37: =IFERROR(J16-(Income_Statement!D17*(1+Assumptions!$B$50)^MAX(0,8)*$B$8),"—") | K37: =IFERROR(K16-(Income_Statement!D17*(1+Assumptions!$B$50)^MAX(0,9)*$B$8),"—")
A38: DSCR (Stressed) | B38: =IFERROR(B37/B19,"—") | C38: =IFERROR(C37/C19,"—") | D38: =IFERROR(D37/D19,"—") | E38: =IFERROR(E37/E19,"—") | F38: =IFERROR(F37/F19,"—") | G38: =IFERROR(G37/G19,"—") | H38: =IFERROR(H37/H19,"—") | I38: =IFERROR(I37/I19,"—") | ... K38: =IFERROR(K37/K19,"—")
A39: CFAT (Stressed) | B39: =B37-B19 | C39: =C37-C19 | D39: =D37-D19 | E39: =E37-E19 | F39: =F37-F19 | G39: =G37-G19 | H39: =H37-H19 | I39: =I37-I19 | ... K39: =K37-K19
A41: Stress C — Refi Rate +100bps (HYPOTHETICAL: 8% vs base 7%)
A42: Hold-period CFAT unchanged. Refi math gets harder. Max refi loan shrinks.
A43: Year | B43: Y1 | C43: Y2 | D43: Y3 | E43: Y4 | F43: Y5 | G43: Y6 | H43: Y7 | I43: Y8 | J43: Y9 | K43: Y10
A44: NOI (Base) | B44: =B16 | C44: =C16 | D44: =D16 | E44: =E16 | F44: =F16 | G44: =G16 | H44: =H16 | I44: =I16 | ... K44: =K16
A45: Stressed Refi Rate | B45: =$B$11+$B$9 | C45: =$B$11+$B$9 | D45: =$B$11+$B$9 | E45: =$B$11+$B$9 | F45: =$B$11+$B$9 | G45: =$B$11+$B$9 | H45: =$B$11+$B$9 | I45: =$B$11+$B$9 | ... K45: =$B$11+$B$9
...

Sheet Refi_Timeline
A1: ZOXIRO — DSCR LOAN HEALTH & REFI TIMELINE (15-Year Horizon)
A2: Year-by-year refi feasibility through Y15 | Tells you exactly WHEN you can refi cleanly | Pulls from Scenarios tab
A4: STRESS KNOBS (pulls from Cash_Flow_10yr inputs)
A5: Rent Haircut % | B5: =Cash_Flow_10yr!B7
A6: OpEx Inflation % | B6: =Cash_Flow_10yr!B8
A7: Refi Rate Add-On | B7: =Cash_Flow_10yr!B9
A8: Exit Cap Add-On | B8: =Cash_Flow_10yr!B10
A9: Base Refi Rate | B9: =Cash_Flow_10yr!B11
A10: Base Exit Cap | B10: =Cash_Flow_10yr!B12
A12: SECTION 1 — BASE CASE (current Scenarios tab structure)
A13: Year | B13: NOI | C13: Senior Bal | D13: Carry Bal | E13: Stack | F13: Asset Value | G13: Max Refi (LTV) | H13: Max Refi (DSCR) | I13: Max Refi | J13: Refi Gap | K13: Cash-Out | L13: OK TO REFI?
A14: Y1 | B14: =Scenarios!D11 | C14: =IFERROR(Scenarios!D18*((1+Scenarios!D19/12)^(Scenarios!D20*12)-(1+Scenarios!D19/12)^(1*12))/((1+Scenarios!D19/12)^(Scenarios!D20*12)-1),"—") | D14: =Scenarios!D27*(1+Scenarios!D28)^1 | E14: =C14+D14 | F14: =IFERROR(B14/$B$10,"—") | G14: =F14*Assumptions!$B$55 | H14: =IFERROR(PV($B$9/12,360,-B14/Assumptions!$B$57/12),"—") | I14: =IFERROR(MIN(G14,H14),"—") | J14: =E14-I14 | K14: =IFERROR(MAX(0,-J14),"—") | L14: =IF(J14<=0,"WAIT","NO")
A15: Y2 | B15: =IFERROR((Scenarios!D11+Scenarios!D12)/2,"—") | C15: =IFERROR(Scenarios!D18*((1+Scenarios!D19/12)^(Scenarios!D20*12)-(1+Scenarios!D19/12)^(2*12))/((1+Scenarios!D19/12)^(Scenarios!D20*12)-1),"—") | D15: =Scenarios!D27*(1+Scenarios!D28)^2 | E15: =C15+D15 | F15: =IFERROR(B15/$B$10,"—") | G15: =F15*Assumptions!$B$55 | H15: =IFERROR(PV($B$9/12,360,-B15/Assumptions!$B$57/12),"—") | I15: =IFERROR(MIN(G15,H15),"—") | J15: =E15-I15 | K15: =IFERROR(MAX(0,-J15),"—") | L15: =IF(J15<=0,"WAIT","NO")
A16: Y3 | B16: =Scenarios!D12 | C16: =IFERROR(Scenarios!D18*((1+Scenarios!D19/12)^(Scenarios!D20*12)-(1+Scenarios!D19/12)^(3*12))/((1+Scenarios!D19/12)^(Scenarios!D20*12)-1),"—") | D16: =Scenarios!D27*(1+Scenarios!D28)^3 | E16: =C16+D16 | F16: =IFERROR(B16/$B$10,"—") | G16: =F16*Assumptions!$B$55 | H16: =IFERROR(PV($B$9/12,360,-B16/Assumptions!$B$57/12),"—") | I16: =IFERROR(MIN(G16,H16),"—") | J16: =E16-I16 | K16: =IFERROR(MAX(0,-J16),"—") | L16: =IF(J16<=0,"WAIT","NO")
A17: Y4 | B17: =Scenarios!D12*((1+Cash_Flow_10yr!$B$5))^(4-3) | C17: =IFERROR(Scenarios!D18*((1+Scenarios!D19/12)^(Scenarios!D20*12)-(1+Scenarios!D19/12)^(4*12))/((1+Scenarios!D19/12)^(Scenarios!D20*12)-1),"—") | D17: =Scenarios!D27*(1+Scenarios!D28)^4 | E17: =C17+D17 | F17: =IFERROR(B17/$B$10,"—") | G17: =F17*Assumptions!$B$55 | H17: =IFERROR(PV($B$9/12,360,-B17/Assumptions!$B$57/12),"—") | I17: =IFERROR(MIN(G17,H17),"—") | J17: =E17-I17 | K17: =IFERROR(MAX(0,-J17),"—") | L17: =IF(J17<=0,"WAIT","NO")
A18: Y5 | B18: =Scenarios!D12*((1+Cash_Flow_10yr!$B$5))^(5-3) | C18: =IFERROR(Scenarios!D18*((1+Scenarios!D19/12)^(Scenarios!D20*12)-(1+Scenarios!D19/12)^(5*12))/((1+Scenarios!D19/12)^(Scenarios!D20*12)-1),"—") | D18: =Scenarios!D27*(1+Scenarios!D28)^5 | E18: =C18+D18 | F18: =IFERROR(B18/$B$10,"—") | G18: =F18*Assumptions!$B$55 | H18: =IFERROR(PV($B$9/12,360,-B18/Assumptions!$B$57/12),"—") | I18: =IFERROR(MIN(G18,H18),"—") | J18: =E18-I18 | K18: =IFERROR(MAX(0,-J18),"—") | L18: =IF(J18<=0,"YES","NO")
A19: Y6 | B19: =Scenarios!D12*((1+Cash_Flow_10yr!$B$5))^(6-3) | C19: =IFERROR(Scenarios!D18*((1+Scenarios!D19/12)^(Scenarios!D20*12)-(1+Scenarios!D19/12)^(6*12))/((1+Scenarios!D19/12)^(Scenarios!D20*12)-1),"—") | D19: =Scenarios!D27*(1+Scenarios!D28)^6 | E19: =C19+D19 | F19: =IFERROR(B19/$B$10,"—") | G19: =F19*Assumptions!$B$55 | H19: =IFERROR(PV($B$9/12,360,-B19/Assumptions!$B$57/12),"—") | I19: =IFERROR(MIN(G19,H19),"—") | J19: =E19-I19 | K19: =IFERROR(MAX(0,-J19),"—") | L19: =IF(J19<=0,"YES","NO")
A20: Y7 | B20: =Scenarios!D12*((1+Cash_Flow_10yr!$B$5))^(7-3) | C20: =IFERROR(Scenarios!D18*((1+Scenarios!D19/12)^(Scenarios!D20*12)-(1+Scenarios!D19/12)^(7*12))/((1+Scenarios!D19/12)^(Scenarios!D20*12)-1),"—") | D20: =Scenarios!D27*(1+Scenarios!D28)^7 | E20: =C20+D20 | F20: =IFERROR(B20/$B$10,"—") | G20: =F20*Assumptions!$B$55 | H20: =IFERROR(PV($B$9/12,360,-B20/Assumptions!$B$57/12),"—") | I20: =IFERROR(MIN(G20,H20),"—") | J20: =E20-I20 | K20: =IFERROR(MAX(0,-J20),"—") | L20: =IF(J20<=0,"YES","NO")
A21: Y8 | B21: =Scenarios!D12*((1+Cash_Flow_10yr!$B$5))^(8-3) | C21: =IFERROR(Scenarios!D18*((1+Scenarios!D19/12)^(Scenarios!D20*12)-(1+Scenarios!D19/12)^(8*12))/((1+Scenarios!D19/12)^(Scenarios!D20*12)-1),"—") | D21: =Scenarios!D27*(1+Scenarios!D28)^8 | E21: =C21+D21 | F21: =IFERROR(B21/$B$10,"—") | G21: =F21*Assumptions!$B$55 | H21: =IFERROR(PV($B$9/12,360,-B21/Assumptions!$B$57/12),"—") | I21: =IFERROR(MIN(G21,H21),"—") | J21: =E21-I21 | K21: =IFERROR(MAX(0,-J21),"—") | L21: =IF(J21<=0,"YES","NO")
A22: Y9 | B22: =Scenarios!D12*((1+Cash_Flow_10yr!$B$5))^(9-3) | C22: =IFERROR(Scenarios!D18*((1+Scenarios!D19/12)^(Scenarios!D20*12)-(1+Scenarios!D19/12)^(9*12))/((1+Scenarios!D19/12)^(Scenarios!D20*12)-1),"—") | D22: =Scenarios!D27*(1+Scenarios!D28)^9 | E22: =C22+D22 | F22: =IFERROR(B22/$B$10,"—") | G22: =F22*Assumptions!$B$55 | H22: =IFERROR(PV($B$9/12,360,-B22/Assumptions!$B$57/12),"—") | I22: =IFERROR(MIN(G22,H22),"—") | J22: =E22-I22 | K22: =IFERROR(MAX(0,-J22),"—") | L22: =IF(J22<=0,"YES","NO")
A23: Y10 | B23: =Scenarios!D12*((1+Cash_Flow_10yr!$B$5))^(10-3) | C23: =IFERROR(Scenarios!D18*((1+Scenarios!D19/12)^(Scenarios!D20*12)-(1+Scenarios!D19/12)^(10*12))/((1+Scenarios!D19/12)^(Scenarios!D20*12)-1),"—") | D23: =Scenarios!D27*(1+Scenarios!D28)^10 | E23: =C23+D23 | F23: =IFERROR(B23/$B$10,"—") | G23: =F23*Assumptions!$B$55 | H23: =IFERROR(PV($B$9/12,360,-B23/Assumptions!$B$57/12),"—") | I23: =IFERROR(MIN(G23,H23),"—") | J23: =E23-I23 | K23: =IFERROR(MAX(0,-J23),"—") | L23: =IF(J23<=0,"YES","NO")
A24: Y11 | B24: =Scenarios!D12*((1+Cash_Flow_10yr!$B$5))^(11-3) | C24: =IFERROR(Scenarios!D18*((1+Scenarios!D19/12)^(Scenarios!D20*12)-(1+Scenarios!D19/12)^(11*12))/((1+Scenarios!D19/12)^(Scenarios!D20*12)-1),"—") | D24: =Scenarios!D27*(1+Scenarios!D28)^11 | E24: =C24+D24 | F24: =IFERROR(B24/$B$10,"—") | G24: =F24*Assumptions!$B$55 | H24: =IFERROR(PV($B$9/12,360,-B24/Assumptions!$B$57/12),"—") | I24: =IFERROR(MIN(G24,H24),"—") | J24: =E24-I24 | K24: =IFERROR(MAX(0,-J24),"—") | L24: =IF(J24<=0,"YES","NO")
A25: Y12 | B25: =Scenarios!D12*((1+Cash_Flow_10yr!$B$5))^(12-3) | C25: =IFERROR(Scenarios!D18*((1+Scenarios!D19/12)^(Scenarios!D20*12)-(1+Scenarios!D19/12)^(12*12))/((1+Scenarios!D19/12)^(Scenarios!D20*12)-1),"—") | D25: =Scenarios!D27*(1+Scenarios!D28)^12 | E25: =C25+D25 | F25: =IFERROR(B25/$B$10,"—") | G25: =F25*Assumptions!$B$55 | H25: =IFERROR(PV($B$9/12,360,-B25/Assumptions!$B$57/12),"—") | I25: =IFERROR(MIN(G25,H25),"—") | J25: =E25-I25 | K25: =IFERROR(MAX(0,-J25),"—") | L25: =IF(J25<=0,"YES","NO")
A26: Y13 | B26: =Scenarios!D12*((1+Cash_Flow_10yr!$B$5))^(13-3) | C26: =IFERROR(Scenarios!D18*((1+Scenarios!D19/12)^(Scenarios!D20*12)-(1+Scenarios!D19/12)^(13*12))/((1+Scenarios!D19/12)^(Scenarios!D20*12)-1),"—") | D26: =Scenarios!D27*(1+Scenarios!D28)^13 | E26: =C26+D26 | F26: =IFERROR(B26/$B$10,"—") | G26: =F26*Assumptions!$B$55 | H26: =IFERROR(PV($B$9/12,360,-B26/Assumptions!$B$57/12),"—") | I26: =IFERROR(MIN(G26,H26),"—") | J26: =E26-I26 | K26: =IFERROR(MAX(0,-J26),"—") | L26: =IF(J26<=0,"YES","NO")
A27: Y14 | B27: =Scenarios!D12*((1+Cash_Flow_10yr!$B$5))^(14-3) | C27: =IFERROR(Scenarios!D18*((1+Scenarios!D19/12)^(Scenarios!D20*12)-(1+Scenarios!D19/12)^(14*12))/((1+Scenarios!D19/12)^(Scenarios!D20*12)-1),"—") | D27: =Scenarios!D27*(1+Scenarios!D28)^14 | E27: =C27+D27 | F27: =IFERROR(B27/$B$10,"—") | G27: =F27*Assumptions!$B$55 | H27: =IFERROR(PV($B$9/12,360,-B27/Assumptions!$B$57/12),"—") | I27: =IFERROR(MIN(G27,H27),"—") | J27: =E27-I27 | K27: =IFERROR(MAX(0,-J27),"—") | L27: =IF(J27<=0,"YES","NO")
A28: Y15 | B28: =Scenarios!D12*((1+Cash_Flow_10yr!$B$5))^(15-3) | C28: =IFERROR(Scenarios!D18*((1+Scenarios!D19/12)^(Scenarios!D20*12)-(1+Scenarios!D19/12)^(15*12))/((1+Scenarios!D19/12)^(Scenarios!D20*12)-1),"—") | D28: =Scenarios!D27*(1+Scenarios!D28)^15 | E28: =C28+D28 | F28: =IFERROR(B28/$B$10,"—") | G28: =F28*Assumptions!$B$55 | H28: =IFERROR(PV($B$9/12,360,-B28/Assumptions!$B$57/12),"—") | I28: =IFERROR(MIN(G28,H28),"—") | J28: =E28-I28 | K28: =IFERROR(MAX(0,-J28),"—") | L28: =IF(J28<=0,"YES","NO")
A29: EARLIEST CLEAN REFI YEAR → | C29: =IFERROR(INDEX($A$14:$A$28,MATCH("YES",$L$14:$L$28,0)),"None within 15 yrs") | E29: Cash-Out at that year: | G29: =IFERROR(INDEX($K$14:$K$28,MATCH("YES",$L$14:$L$28,0)),0)
A31: SECTION 2 — STRESS A: Rents Haircut (vacancy spike or market softening)
A32: Year | B32: NOI | C32: Senior Bal | D32: Carry Bal | E32: Stack | F32: Asset Value | G32: Max Refi (LTV) | H32: Max Refi (DSCR) | I32: Max Refi | J32: Refi Gap | K32: Cash-Out | L32: OK TO REFI?
A33: Y1 | B33: =IFERROR(Scenarios!D11-(Income_Statement!D5*((1+Cash_Flow_10yr!$B$5))^MAX(0,0))*$B$5,"—") | C33: =IFERROR(Scenarios!D18*((1+Scenarios!D19/12)^(Scenarios!D20*12)-(1+Scenarios!D19/12)^(1*12))/((1+Scenarios!D19/12)^(Scenarios!D20*12)-1),"—") | D33: =Scenarios!D27*(1+Scenarios!D28)^1 | E33: =C33+D33 | F33: =IFERROR(B33/$B$10,"—") | G33: =F33*Assumptions!$B$55 | H33: =IFERROR(PV($B$9/12,360,-B33/Assumptions!$B$57/12),"—") | I33: =IFERROR(MIN(G33,H33),"—") | J33: =E33-I33 | K33: =IFERROR(MAX(0,-J33),"—") | L33: =IF(J33<=0,"WAIT","NO")
A34: Y2 | B34: =IFERROR((Scenarios!D11+Scenarios!D12)/2-(Income_Statement!D5*((1+Cash_Flow_10yr!$B$5))^MAX(0,1))*$B$5,"—") | C34: =IFERROR(Scenarios!D18*((1+Scenarios!D19/12)^(Scenarios!D20*12)-(1+Scenarios!D19/12)^(2*12))/((1+Scenarios!D19/12)^(Scenarios!D20*12)-1),"—") | D34: =Scenarios!D27*(1+Scenarios!D28)^2 | E34: =C34+D34 | F34: =IFERROR(B34/$B$10,"—") | G34: =F34*Assumptions!$B$55 | H34: =IFERROR(PV($B$9/12,360,-B34/Assumptions!$B$57/12),"—") | I34: =IFERROR(MIN(G34,H34),"—") | J34: =E34-I34 | K34: =IFERROR(MAX(0,-J34),"—") | L34: =IF(J34<=0,"WAIT","NO")
A35: Y3 | B35: =IFERROR(Scenarios!D12-(Income_Statement!D5*((1+Cash_Flow_10yr!$B$5))^MAX(0,2))*$B$5,"—") | C35: =IFERROR(Scenarios!D18*((1+Scenarios!D19/12)^(Scenarios!D20*12)-(1+Scenarios!D19/12)^(3*12))/((1+Scenarios!D19/12)^(Scenarios!D20*12)-1),"—") | D35: =Scenarios!D27*(1+Scenarios!D28)^3 | E35: =C35+D35 | F35: =IFERROR(B35/$B$10,"—") | G35: =F35*Assumptions!$B$55 | H35: =IFERROR(PV($B$9/12,360,-B35/Assumptions!$B$57/12),"—") | I35: =IFERROR(MIN(G35,H35),"—") | J35: =E35-I35 | K35: =IFERROR(MAX(0,-J35),"—") | L35: =IF(J35<=0,"WAIT","NO")
A36: Y4 | B36: =IFERROR(Scenarios!D12*((1+Cash_Flow_10yr!$B$5))^(4-3)-(Income_Statement!D5*((1+Cash_Flow_10yr!$B$5))^MAX(0,3))*$B$5,"—") | C36: =IFERROR(Scenarios!D18*((1+Scenarios!D19/12)^(Scenarios!D20*12)-(1+Scenarios!D19/12)^(4*12))/((1+Scenarios!D19/12)^(Scenarios!D20*12)-1),"—") | D36: =Scenarios!D27*(1+Scenarios!D28)^4 | E36: =C36+D36 | F36: =IFERROR(B36/$B$10,"—") | G36: =F36*Assumptions!$B$55 | H36: =IFERROR(PV($B$9/12,360,-B36/Assumptions!$B$57/12),"—") | I36: =IFERROR(MIN(G36,H36),"—") | J36: =E36-I36 | K36: =IFERROR(MAX(0,-J36),"—") | L36: =IF(J36<=0,"WAIT","NO")
A37: Y5 | B37: =IFERROR(Scenarios!D12*((1+Cash_Flow_10yr!$B$5))^(5-3)-(Income_Statement!D5*((1+Cash_Flow_10yr!$B$5))^MAX(0,4))*$B$5,"—") | C37: =IFERROR(Scenarios!D18*((1+Scenarios!D19/12)^(Scenarios!D20*12)-(1+Scenarios!D19/12)^(5*12))/((1+Scenarios!D19/12)^(Scenarios!D20*12)-1),"—") | D37: =Scenarios!D27*(1+Scenarios!D28)^5 | E37: =C37+D37 | F37: =IFERROR(B37/$B$10,"—") | G37: =F37*Assumptions!$B$55 | H37: =IFERROR(PV($B$9/12,360,-B37/Assumptions!$B$57/12),"—") | I37: =IFERROR(MIN(G37,H37),"—") | J37: =E37-I37 | K37: =IFERROR(MAX(0,-J37),"—") | L37: =IF(J37<=0,"YES","NO")
A38: Y6 | B38: =IFERROR(Scenarios!D12*((1+Cash_Flow_10yr!$B$5))^(6-3)-(Income_Statement!D5*((1+Cash_Flow_10yr!$B$5))^MAX(0,5))*$B$5,"—") | C38: =IFERROR(Scenarios!D18*((1+Scenarios!D19/12)^(Scenarios!D20*12)-(1+Scenarios!D19/12)^(6*12))/((1+Scenarios!D19/12)^(Scenarios!D20*12)-1),"—") | D38: =Scenarios!D27*(1+Scenarios!D28)^6 | E38: =C38+D38 | F38: =IFERROR(B38/$B$10,"—") | G38: =F38*Assumptions!$B$55 | H38: =IFERROR(PV($B$9/12,360,-B38/Assumptions!$B$57/12),"—") | I38: =IFERROR(MIN(G38,H38),"—") | J38: =E38-I38 | K38: =IFERROR(MAX(0,-J38),"—") | L38: =IF(J38<=0,"YES","NO")
A39: Y7 | B39: =IFERROR(Scenarios!D12*((1+Cash_Flow_10yr!$B$5))^(7-3)-(Income_Statement!D5*((1+Cash_Flow_10yr!$B$5))^MAX(0,6))*$B$5,"—") | C39: =IFERROR(Scenarios!D18*((1+Scenarios!D19/12)^(Scenarios!D20*12)-(1+Scenarios!D19/12)^(7*12))/((1+Scenarios!D19/12)^(Scenarios!D20*12)-1),"—") | D39: =Scenarios!D27*(1+Scenarios!D28)^7 | E39: =C39+D39 | F39: =IFERROR(B39/$B$10,"—") | G39: =F39*Assumptions!$B$55 | H39: =IFERROR(PV($B$9/12,360,-B39/Assumptions!$B$57/12),"—") | I39: =IFERROR(MIN(G39,H39),"—") | J39: =E39-I39 | K39: =IFERROR(MAX(0,-J39),"—") | L39: =IF(J39<=0,"YES","NO")
A40: Y8 | B40: =IFERROR(Scenarios!D12*((1+Cash_Flow_10yr!$B$5))^(8-3)-(Income_Statement!D5*((1+Cash_Flow_10yr!$B$5))^MAX(0,7))*$B$5,"—") | C40: =IFERROR(Scenarios!D18*((1+Scenarios!D19/12)^(Scenarios!D20*12)-(1+Scenarios!D19/12)^(8*12))/((1+Scenarios!D19/12)^(Scenarios!D20*12)-1),"—") | D40: =Scenarios!D27*(1+Scenarios!D28)^8 | E40: =C40+D40 | F40: =IFERROR(B40/$B$10,"—") | G40: =F40*Assumptions!$B$55 | H40: =IFERROR(PV($B$9/12,360,-B40/Assumptions!$B$57/12),"—") | I40: =IFERROR(MIN(G40,H40),"—") | J40: =E40-I40 | K40: =IFERROR(MAX(0,-J40),"—") | L40: =IF(J40<=0,"YES","NO")
A41: Y9 | B41: =IFERROR(Scenarios!D12*((1+Cash_Flow_10yr!$B$5))^(9-3)-(Income_Statement!D5*((1+Cash_Flow_10yr!$B$5))^MAX(0,8))*$B$5,"—") | C41: =IFERROR(Scenarios!D18*((1+Scenarios!D19/12)^(Scenarios!D20*12)-(1+Scenarios!D19/12)^(9*12))/((1+Scenarios!D19/12)^(Scenarios!D20*12)-1),"—") | D41: =Scenarios!D27*(1+Scenarios!D28)^9 | E41: =C41+D41 | F41: =IFERROR(B41/$B$10,"—") | G41: =F41*Assumptions!$B$55 | H41: =IFERROR(PV($B$9/12,360,-B41/Assumptions!$B$57/12),"—") | I41: =IFERROR(MIN(G41,H41),"—") | J41: =E41-I41 | K41: =IFERROR(MAX(0,-J41),"—") | L41: =IF(J41<=0,"YES","NO")
A42: Y10 | B42: =IFERROR(Scenarios!D12*((1+Cash_Flow_10yr!$B$5))^(10-3)-(Income_Statement!D5*((1+Cash_Flow_10yr!$B$5))^MAX(0,9))*$B$5,"—") | C42: =IFERROR(Scenarios!D18*((1+Scenarios!D19/12)^(Scenarios!D20*12)-(1+Scenarios!D19/12)^(10*12))/((1+Scenarios!D19/12)^(Scenarios!D20*12)-1),"—") | D42: =Scenarios!D27*(1+Scenarios!D28)^10 | E42: =C42+D42 | F42: =IFERROR(B42/$B$10,"—") | G42: =F42*Assumptions!$B$55 | H42: =IFERROR(PV($B$9/12,360,-B42/Assumptions!$B$57/12),"—") | I42: =IFERROR(MIN(G42,H42),"—") | J42: =E42-I42 | K42: =IFERROR(MAX(0,-J42),"—") | L42: =IF(J42<=0,"YES","NO")
A43: Y11 | B43: =IFERROR(Scenarios!D12*((1+Cash_Flow_10yr!$B$5))^(11-3)-(Income_Statement!D5*((1+Cash_Flow_10yr!$B$5))^MAX(0,10))*$B$5,"—") | C43: =IFERROR(Scenarios!D18*((1+Scenarios!D19/12)^(Scenarios!D20*12)-(1+Scenarios!D19/12)^(11*12))/((1+Scenarios!D19/12)^(Scenarios!D20*12)-1),"—") | D43: =Scenarios!D27*(1+Scenarios!D28)^11 | E43: =C43+D43 | F43: =IFERROR(B43/$B$10,"—") | G43: =F43*Assumptions!$B$55 | H43: =IFERROR(PV($B$9/12,360,-B43/Assumptions!$B$57/12),"—") | I43: =IFERROR(MIN(G43,H43),"—") | J43: =E43-I43 | K43: =IFERROR(MAX(0,-J43),"—") | L43: =IF(J43<=0,"YES","NO")
...

Sheet Refi_Analysis
A1: REFINANCE ANALYSIS — at the balloon year
B3: Property 1 | C3: Property 2 | D3: Combined
A4: PROJECTED NOI AT REFI (uses Refi Year from Assumptions)
A5: Refi Year (blank on Assumptions = earliest year it actually clears) | B5: =IFERROR(IF(Assumptions!B53="",VALUE(SUBSTITUTE(Refi_Timeline!$C$29,"Y","")),Assumptions!B53),10) | C5: =IFERROR(IF(Assumptions!E53="",VALUE(SUBSTITUTE(Refi_Timeline!$C$29,"Y","")),Assumptions!E53),10) | D5: =B5
A6: NOI at Refi (projected) | B6: =IFERROR(IF(Assumptions!B53<=3,Income_Statement!B21+(Scenarios!B12-Income_Statement!B21)*(Assumptions!B53/3),Scenarios!B12*(1+Assumptions!B41)^(Assumptions!B53-3)),"—") | C6: =IFERROR(IF(Assumptions!E53<=3,Income_Statement!C21+(Scenarios!C12-Income_Statement!C21)*(Assumptions!E53/3),Scenarios!C12*(1+Assumptions!E41)^(Assumptions!E53-3)),"—") | D6: =B6+C6
A8: REFI VALUATION
A9: Exit Cap Rate | B9: =Assumptions!B54 | C9: =Assumptions!E54 | D9: =IFERROR(AVERAGE(B9,C9),"—")
A10: Stabilized Asset Value at Refi | B10: =IFERROR(B6/B9,"—") | C10: =IFERROR(C6/C9,"—") | D10: =B10+C10
A11: vs. Original Purchase Price | B11: =B10-Assumptions!B6 | C11: =C10-Assumptions!E6 | D11: =B11+C11
A12: Appreciation % | B12: =IFERROR(B10/Assumptions!B6-1,"—") | C12: =IFERROR(C10/Assumptions!E6-1,"—") | D12: =IFERROR(D10/Assumptions!H6-1,"—")
A14: MAX REFI LOAN (Lower of LTV or DSCR)
A15: Refi Rate | B15: =Assumptions!B56 | C15: =Assumptions!E56 | D15: =IFERROR(AVERAGE(B15,C15),"—")
A16: Refi LTV % | B16: =Assumptions!B55 | C16: =Assumptions!E55 | D16: =IFERROR(AVERAGE(B16,C16),"—")
A17: Refi Min DSCR | B17: =Assumptions!B57 | C17: =Assumptions!E57 | D17: =IFERROR(AVERAGE(B17,C17),"—")
A18: Max Loan by LTV | B18: =B10*B16 | C18: =C10*C16 | D18: =B18+C18
A19: Max Loan by DSCR (1.25x, 30yr amort) | B19: =IFERROR(PV(B15/12,360,-B6/B17/12),"—") | C19: =IFERROR(PV(C15/12,360,-C6/C17/12),"—") | D19: =B19+C19
A20: MAX REFI LOAN (Limiting) | B20: =IFERROR(MIN(B18,B19),"—") | C20: =IFERROR(MIN(C18,C19),"—") | D20: =B20+C20
A21: Limiting Constraint | B21: =IF(B18<B19,"LTV","DSCR") | C21: =IF(C18<C19,"LTV","DSCR")
A23: REFI PAYOFF — DOES IT CLEAR THE STACK?
A24: Senior Loan Balance at Refi | B24: =IFERROR(Assumptions!B13*(((1+Assumptions!B14/12)^(Assumptions!B15*12)-(1+Assumptions!B14/12)^(Assumptions!B53*12))/((1+Assumptions!B14/12)^(Assumptions!B15*12)-1)),"—") | C24: =IFERROR(Assumptions!E13*(((1+Assumptions!E14/12)^(Assumptions!E15*12)-(1+Assumptions!E14/12)^(Assumptions!E53*12))/((1+Assumptions!E14/12)^(Assumptions!E15*12)-1)),"—") | D24: =B24+C24
A25: Seller Carry Balance at Refi (incl. accrual) | B25: =IF(Assumptions!B23=3,Scenarios!B27*(1+Scenarios!B28)^Assumptions!B53,Scenarios!B27) | C25: =IF(Assumptions!E23=3,Scenarios!C27*(1+Scenarios!C28)^Assumptions!E53,Scenarios!C27) | D25: =B25+C25
A26: Total Stack Balance at Refi | B26: =B24+B25 | C26: =C24+C25 | D26: =B26+C26
A27: Refi Loan Available | B27: =B20 | C27: =C20 | D27: =B27+C27
A28: REFI GAP (Negative = Cash Out, Positive = Shortfall) | B28: =B26-B27 | C28: =C26-C27 | D28: =B28+C28
A29: REFI VERDICT | B29: =IF(B28<=0,"PASS — CASH OUT",IF(Scenarios!B49>=B28,"GAP COVERED BY BUYER CASH","NEEDS PLAN")) | C29: =IF(C28<=0,"PASS — CASH OUT",IF(Scenarios!C49>=C28,"GAP COVERED BY BUYER CASH","NEEDS PLAN")) | D29: =IF(D28<=0,"PASS — CASH OUT",IF(Scenarios!D49>=D28,"GAP COVERED BY BUYER CASH","NEEDS PLAN"))
A31: REQUIRED NOI TO CLEAR REFI (Solve Backwards)
A32: Required Refi Loan = Stack Balance | B32: =B26 | C32: =C26 | D32: =D26
A33: Implied Asset Value Required (at LTV) | B33: =IFERROR(B32/B16,"—") | C33: =IFERROR(C32/C16,"—") | D33: =B33+C33
A34: Implied NOI Required (at Cap Rate) | B34: =B33*B9 | C34: =C33*C9 | D34: =B34+C34
A35: Required NOI Growth from Y1 | B35: =IFERROR(B34/Income_Statement!B21-1,"—") | C35: =IFERROR(C34/Income_Statement!C21-1,"—") | D35: =IFERROR(D34/Income_Statement!D21-1,"—")

Sheet Deal_Score
A1: DEAL SCORECARD — 0-100 POINTS
A3: Category | B3: Test | C3: Property 1 | D3: Property 2 | E3: Combined
A4: DSCR Health (25 pts)
A5: DSCR — Total Debt | B5: ≥1.30x = 25, 1.20-1.30 = 18, 1.10-1.20 = 10, 1.0-1.10 = 5, <1.0 = 0 | C5: =IF(Income_Statement!B29>=1.3,25,IF(Income_Statement!B29>=1.2,18,IF(Income_Statement!B29>=1.1,10,IF(Income_Statement!B29>=1,5,0)))) | D5: =IF(Income_Statement!C29>=1.3,25,IF(Income_Statement!C29>=1.2,18,IF(Income_Statement!C29>=1.1,10,IF(Income_Statement!C29>=1,5,0)))) | E5: =IF(Income_Statement!D29>=1.3,25,IF(Income_Statement!D29>=1.2,18,IF(Income_Statement!D29>=1.1,10,IF(Income_Statement!D29>=1,5,0))))
A6: Refi Exit (25 pts)
A7: Refi Gap | B7: Cash Out >$25K = 25, Clears = 18, Covered by buyer cash + 5yr CFAT = 15, Covered by buyer cash only = 10, Otherwise 0 | C7: =IF(Refi_Analysis!B28<=-25000,25,IF(Refi_Analysis!B28<=0,18,IF(Scenarios!B49+Scenarios!B55*5>=Refi_Analysis!B28,15,IF(Scenarios!B49>=Refi_Analysis!B28,10,0)))) | D7: =IF(Refi_Analysis!C28<=-25000,25,IF(Refi_Analysis!C28<=0,18,IF(Scenarios!C49+Scenarios!C55*5>=Refi_Analysis!C28,15,IF(Scenarios!C49>=Refi_Analysis!C28,10,0)))) | E7: =IF(Refi_Analysis!D28<=-25000,25,IF(Refi_Analysis!D28<=0,18,IF(Scenarios!D49+Scenarios!D55*5>=Refi_Analysis!D28,15,IF(Scenarios!D49>=Refi_Analysis!D28,10,0))))
A8: Cash Flow (15 pts)
A9: Y1 Cash Flow After Debt Service | B9: >$10K = 15, $5-10K = 10, $0-5K = 5, ≤$0 = 0 | C9: =IF(Income_Statement!B30>10000,15,IF(Income_Statement!B30>5000,10,IF(Income_Statement!B30>0,5,0))) | D9: =IF(Income_Statement!C30>10000,15,IF(Income_Statement!C30>5000,10,IF(Income_Statement!C30>0,5,0))) | E9: =IF(Income_Statement!D30>20000,15,IF(Income_Statement!D30>10000,10,IF(Income_Statement!D30>0,5,0)))
A10: Going-In Cap Rate (10 pts)
A11: Cap Rate vs. your market target (set on Assumptions) | B11: ≥ target = 10, within 1 pt = 7, within 2 pts = 4, below = 0 | C11: =IF(Income_Statement!B22>=Assumptions!$B$58,10,IF(Income_Statement!B22>=Assumptions!$B$58-0.01,7,IF(Income_Statement!B22>=Assumptions!$B$58-0.02,4,0))) | D11: =IF(Income_Statement!C22>=Assumptions!$B$58,10,IF(Income_Statement!C22>=Assumptions!$B$58-0.01,7,IF(Income_Statement!C22>=Assumptions!$B$58-0.02,4,0))) | E11: =IF(Income_Statement!D22>=Assumptions!$B$58,10,IF(Income_Statement!D22>=Assumptions!$B$58-0.01,7,IF(Income_Statement!D22>=Assumptions!$B$58-0.02,4,0)))
A14: Operating Efficiency (10 pts)
A15: OpEx Ratio | B15: ≤45% = 10, 45-55% = 7, 55-65% = 4, >65% = 0 | C15: =IF(Income_Statement!B18<=0.45,10,IF(Income_Statement!B18<=0.55,7,IF(Income_Statement!B18<=0.65,4,0))) | D15: =IF(Income_Statement!C18<=0.45,10,IF(Income_Statement!C18<=0.55,7,IF(Income_Statement!C18<=0.65,4,0))) | E15: =IF(Income_Statement!D18<=0.45,10,IF(Income_Statement!D18<=0.55,7,IF(Income_Statement!D18<=0.65,4,0)))
A16: Long-term DSCR (15 pts)
A17: Y10 DSCR (combined) | B17: ≥1.50x = 15, 1.30-1.50 = 10, 1.20-1.30 = 5, <1.20 = 0 | C17: =IF(Cash_Flow_10yr!K20>=1.5,15,IF(Cash_Flow_10yr!K20>=1.3,10,IF(Cash_Flow_10yr!K20>=1.2,5,0))) | D17: =IF(Cash_Flow_10yr!K20>=1.5,15,IF(Cash_Flow_10yr!K20>=1.3,10,IF(Cash_Flow_10yr!K20>=1.2,5,0))) | E17: =IF(Cash_Flow_10yr!K20>=1.5,15,IF(Cash_Flow_10yr!K20>=1.3,10,IF(Cash_Flow_10yr!K20>=1.2,5,0)))
A19: TOTAL DEAL SCORE | B19: Out of 100 | C19: =IFERROR(MIN(100,C5+C7+C9+C11+C15+C17),"—") | D19: =IFERROR(MIN(100,D5+D7+D9+D11+D15+D17),"—") | E19: =IFERROR(MIN(100,E5+E7+E9+E11+E15+E17),"—")
A20: VERDICT | C20: =IF(C19>=80,"STRONG — DO DILIGENCE",IF(C19>=65,"NEGOTIATE",IF(C19>=50,"RESTRUCTURE","WALK"))) | D20: =IF(D19>=80,"STRONG — DO DILIGENCE",IF(D19>=65,"NEGOTIATE",IF(D19>=50,"RESTRUCTURE","WALK"))) | E20: =IF(E19>=80,"STRONG — DO DILIGENCE",IF(E19>=65,"NEGOTIATE",IF(E19>=50,"RESTRUCTURE","WALK")))

Sheet Kill_Flags
A1: UNDERWRITING KILL FLAGS
A3: Risk Test | B3: Property 1 | C3: Property 2 | D3: Combined | E3: Context / Why This Matters
A4: DSCR Y1 < 1.20x? | B4: =IF(Income_Statement!B29<1.2,"FLAG","OK") | C4: =IF(Income_Statement!C29<1.2,"FLAG","OK") | D4: =IF(Income_Statement!D29<1.2,"FLAG","OK") | E4: Below ~1.20x, most DSCR lenders decline or reprice. If one property fails standalone, check whether cross-collateralising with another lifts the combined ratio.
A5: Refi gap > $0 (shortfall)? | B5: =IF(Refi_Analysis!B28>0,"FLAG","OK") | C5: =IF(Refi_Analysis!C28>0,"FLAG","OK") | D5: =IF(Refi_Analysis!D28>0,"FLAG","OK") | E5: A refi gap means the balloon payoff exceeds what the property can refinance. Cover it from buyer cash at close, accumulated cash flow, or a longer balloon — or the structure does not work.
A6: Going-in cap < 7%? | B6: =IF(Income_Statement!B22<0.07,"FLAG","OK") | C6: =IF(Income_Statement!C22<0.07,"FLAG","OK") | D6: =IF(Income_Statement!D22<0.07,"FLAG","OK") | E6: Going-in cap below your market target usually means a value-add story — RUBS, mark-to-market rents, expense control. Make sure the lift is real and time it honestly; a thin going-in cap with no plan is just an expensive deal.
A7: Negative cash flow Y1? | B7: =IF(Income_Statement!B30<0,"FLAG","OK") | C7: =IF(Income_Statement!C30<0,"FLAG","OK") | D7: =IF(Income_Statement!D30<0,"FLAG","OK") | E7: Pass — positive cash flow Y1 across all parcels.
A8: OpEx ratio > 55%? | B8: =IF(Income_Statement!B18>0.55,"FLAG","OK") | C8: =IF(Income_Statement!C18>0.55,"FLAG","OK") | D8: =IF(Income_Statement!D18>0.55,"FLAG","OK") | E8: Pass — OpEx ratios are within healthy range for C-class.
A9: Cash to close > $30K? | B9: =IF(Assumptions!B27>30000,"FLAG","OK") | C9: =IF(Assumptions!E27>30000,"FLAG","OK") | D9: =IF(Assumptions!B27+Assumptions!E27>60000,"FLAG","OK") | E9: Buyer cash to close should be a number you can actually fund. If negative, confirm where the cash comes from and that every lien is disclosed to the senior lender.
A10: Senior LTV > 80%? | B10: =IF(Assumptions!B12>0.8,"FLAG","OK") | C10: =IF(Assumptions!E12>0.8,"FLAG","OK") | D10: =IFERROR(IF(MAX(Assumptions!B12,Assumptions!E12)>0.8,"FLAG","OK"),"—") | E10: Pass — Senior at 65% LTV, well within DSCR lender max of ~75%.
A11: Seller carry > 60% of price? | B11: =IF(Assumptions!B19>0.6,"FLAG","OK") | C11: =IF(Assumptions!E19>0.6,"FLAG","OK") | D11: =IFERROR(IF(MAX(Assumptions!B19,Assumptions!E19)>0.6,"FLAG","OK"),"—") | E11: Above ~60% the seller is financing most of the deal. That can work, but it concentrates risk with one party and most senior lenders will scrutinise it. Confirm the senior lender has approved the carry in writing.
A12: Required NOI growth > 80%? | B12: =IF(Refi_Analysis!B35>0.8,"FLAG","OK") | C12: =IF(Refi_Analysis!C35>0.8,"FLAG","OK") | D12: =IF(Refi_Analysis!D35>0.8,"FLAG","OK") | E12: Needing NOI to grow more than ~80% to make the exit work is a heavy value-add assumption. Check the rent comps support it and that your timeline is realistic.
A13: Y10 DSCR < 1.20x? | B13: =IF(Cash_Flow_10yr!K20<1.2,"FLAG","OK") | C13: =IF(Cash_Flow_10yr!K20<1.2,"FLAG","OK") | D13: =IF(Cash_Flow_10yr!K20<1.2,"FLAG","OK") | E13: Long-run DSCR at the balloon year. Below 1.20x, plan on refinancing into a lower loan amount or bringing cash.
A14: Cash-on-cash below floor? | B14: =IFERROR(IF(Income_Statement!B41="FAIL","FLAG","OK"),"OK") | C14: =IFERROR(IF(Income_Statement!C41="FAIL","FLAG","OK"),"OK") | D14: =IFERROR(IF(Income_Statement!D41="FAIL","FLAG","OK"),"OK") | E14: Your money has to earn its keep. Below the floor the deal survives but is not worth doing at this structure.
A15: TOTAL FLAGS | B15: =COUNTIF(B4:B14,"FLAG") | C15: =COUNTIF(C4:C14,"FLAG") | D15: =COUNTIF(D4:D14,"FLAG")
A17: REAL CONCERNS (after context): | B17: =IF(B4="FLAG",1,0)+IF(B6="FLAG",1,0)+IF(B14="FLAG",1,0) | C17: =IF(C4="FLAG",1,0)+IF(C6="FLAG",1,0)+IF(C14="FLAG",1,0) | D17: =IF(D4="FLAG",1,0)+IF(D6="FLAG",1,0)+IF(D14="FLAG",1,0) | E17: Excludes the structural flags above (carry %, refi gap, NOI growth) — those are judgement calls, not automatic kills.
A18: VERDICT | B18: =IF(B17=0,"PASS",IF(B17=1,"REVIEW","STRUCTURAL ISSUES")) | C18: =IF(C17=0,"PASS",IF(C17=1,"REVIEW","STRUCTURAL ISSUES")) | D18: =IF(D17=0,"PASS",IF(D17=1,"REVIEW","STRUCTURAL ISSUES"))

Sheet Offers
A1: ZOXIRO — FOUR OFFERS, ONE PROPERTY
A2: ★ = you set it. Move the levers, not the property. Every offer faces the same two gates.
A4: THE DEAL — same for all four
A5: Year-1 NOI — ACTUAL, never pro forma ★
A6: Seller's asking price ★
A7: DSCR floor ★ | B7: 1.25
A8: Cash-on-cash floor ★ | B8: 0.15
A9: A lender will not lend on a pro forma. If NOI above is a projection, the bank offer is already off the table.
A11: WHAT EACH OFFER IS | B11: Their terms | C11: Price lever | D11: Rate lever | E11: Structure lever
A13: THE LEVERS
A14: Price ★ | B14: =$B$6 | C14: =$B$6 | D14: =$B$6 | E14: =$B$6
A15: Down payment % ★ | B15: 0.25 | C15: 0.25 | D15: 0.25 | E15: 0.25
A16: Interest rate ★ | B16: 0.05 | C16: 0.05 | D16: 0.05 | E16: 0.05
A17: Amortisation (yrs) ★ | B17: 30 | C17: 30 | D17: 30 | E17: 30
A18: Balloon (yrs) ★ | B18: 7 | C18: 7 | D18: 7 | E18: 7
A20: STRUCTURE
A21: Down payment $ | B21: =IFERROR(B14*B15,"—") | C21: =IFERROR(C14*C15,"—") | D21: =IFERROR(D14*D15,"—") | E21: =IFERROR(E14*E15,"—")
A22: Amount financed (loan or seller carry) | B22: =IFERROR(B14-B21,"—") | C22: =IFERROR(C14-C21,"—") | D22: =IFERROR(D14-D21,"—") | E22: =IFERROR(E14-E21,"—")
A23: Annual debt service | B23: =IFERROR(-PMT(B16/12,B17*12,B22)*12,"—") | C23: =IFERROR(-PMT(C16/12,C17*12,C22)*12,"—") | D23: =IFERROR(-PMT(D16/12,D17*12,D22)*12,"—") | E23: =IFERROR(-PMT(E16/12,E17*12,E22)*12,"—")
A24: Balance owed at balloon | B24: =IFERROR(-FV(B16/12,B18*12,PMT(B16/12,B17*12,B22),B22),"—") | C24: =IFERROR(-FV(C16/12,C18*12,PMT(C16/12,C17*12,C22),C22),"—") | D24: =IFERROR(-FV(D16/12,D18*12,PMT(D16/12,D17*12,D22),D22),"—") | E24: =IFERROR(-FV(E16/12,E18*12,PMT(E16/12,E17*12,E22),E22),"—")
A26: WHO BRINGS THE DOWN PAYMENT
A27: Transactional funding — % of down covered ★ | B27: 0 | C27: 0 | D27: 0 | E27: 0
A28: Transactional funding $ | B28: =IFERROR(B21*B27,"—") | C28: =IFERROR(C21*C27,"—") | D28: =IFERROR(D21*D27,"—") | E28: =IFERROR(E21*E27,"—")
A29: Funder fee % ★ | B29: 0 | C29: 0 | D29: 0 | E29: 0
A30: Funder fee $ | B30: =IFERROR(B28*B29,"—") | C30: =IFERROR(C28*C29,"—") | D30: =IFERROR(D28*D29,"—") | E30: =IFERROR(E28*E29,"—")
A31: The funder's money is short-term and repaid at the second closing — it is never equity. Fee is a real cost; never default it.
A33: YOUR CASH IN — the denominator that decides cash-on-cash
A34: Down payment you actually pay | B34: =IFERROR(B21-B28,"—") | C34: =IFERROR(C21-C28,"—") | D34: =IFERROR(D21-D28,"—") | E34: =IFERROR(E21-E28,"—")
A35: Closing costs ★ | B35: 0 | C35: 0 | D35: 0 | E35: 0
A36: Prepaid taxes, insurance, reserves ★ | B36: 0 | C36: 0 | D36: 0 | E36: 0
A37: Day-one capex ★ | B37: 0 | C37: 0 | D37: 0 | E37: 0
A38: Funder fee | B38: =B30 | C38: =C30 | D38: =D30 | E38: =E30
A39: TOTAL CASH INVESTED | B39: =IFERROR(SUM(B34:B38),"—") | C39: =IFERROR(SUM(C34:C38),"—") | D39: =IFERROR(SUM(D34:D38),"—") | E39: =IFERROR(SUM(E34:E38),"—")
A41: THE TWO GATES
A42: Annual cash flow after debt service | B42: =IFERROR($B$5-B23,"—") | C42: =IFERROR($B$5-C23,"—") | D42: =IFERROR($B$5-D23,"—") | E42: =IFERROR($B$5-E23,"—")
A43: DSCR | B43: =IFERROR(IF(B23=0,"no debt",$B$5/B23),"—") | C43: =IFERROR(IF(C23=0,"no debt",$B$5/C23),"—") | D43: =IFERROR(IF(D23=0,"no debt",$B$5/D23),"—") | E43: =IFERROR(IF(E23=0,"no debt",$B$5/E23),"—")
A44: DSCR gate | B44: =IFERROR(IF(B23=0,"n/a",IF(B43>=$B$7,"PASS","FAIL")),"—") | C44: =IFERROR(IF(C23=0,"n/a",IF(C43>=$B$7,"PASS","FAIL")),"—") | D44: =IFERROR(IF(D23=0,"n/a",IF(D43>=$B$7,"PASS","FAIL")),"—") | E44: =IFERROR(IF(E23=0,"n/a",IF(E43>=$B$7,"PASS","FAIL")),"—")
A45: Cash-on-cash return | B45: =IFERROR(B42/B39,"—") | C45: =IFERROR(C42/C39,"—") | D45: =IFERROR(D42/D39,"—") | E45: =IFERROR(E42/E39,"—")
A46: Cash-on-cash gate | B46: =IFERROR(IF(B45>=$B$8,"PASS","FAIL"),"—") | C46: =IFERROR(IF(C45>=$B$8,"PASS","FAIL"),"—") | D46: =IFERROR(IF(D45>=$B$8,"PASS","FAIL"),"—") | E46: =IFERROR(IF(E45>=$B$8,"PASS","FAIL"),"—")
A47: VERDICT | B47: =IFERROR(IF(AND(B44<>"FAIL",B46<>"FAIL"),"CLEARS",IF(AND(B44="FAIL",B46="FAIL"),"FAILS BOTH",IF(B44="FAIL","FAILS DSCR","FAILS CASH-ON-CASH"))),"—") | C47: =IFERROR(IF(AND(C44<>"FAIL",C46<>"FAIL"),"CLEARS",IF(AND(C44="FAIL",C46="FAIL"),"FAILS BOTH",IF(C44="FAIL","FAILS DSCR","FAILS CASH-ON-CASH"))),"—") | D47: =IFERROR(IF(AND(D44<>"FAIL",D46<>"FAIL"),"CLEARS",IF(AND(D44="FAIL",D46="FAIL"),"FAILS BOTH",IF(D44="FAIL","FAILS DSCR","FAILS CASH-ON-CASH"))),"—") | E47: =IFERROR(IF(AND(E44<>"FAIL",E46<>"FAIL"),"CLEARS",IF(AND(E44="FAIL",E46="FAIL"),"FAILS BOTH",IF(E44="FAIL","FAILS DSCR","FAILS CASH-ON-CASH"))),"—")
...

Sheet Land
A1: ZOXIRO — LAND
A2: Land has no NOI. Nothing on the income tabs applies. ★ = you set it.
A4: 1. NAME THE PLAY — it decides everything after it
A5: Play (1–6) ★ | B5: 1 | C5: 1 Wholesale · 2 Resale · 3 Owner-financed · 4 Entitlement · 5 Development · 6 Income land
A6: Play in words | B6: =IFERROR(CHOOSE(B5,"Wholesale / assignment — no hold, screen on the spread","Resale flip — short hold, screen on margin over all-in","Owner-financed resale — exit is paper, underwrite the note too","Entitlement — the approval IS the deal","Development residual — land is what is left over","Income land — has real rent, use the income tabs not this one"),"—")
A7: If play = 6, stop. Income land has contractual rent — underwrite it on Assumptions / Income_Statement like any income asset.
A9: 2. THE KILL FILTER — answer these before any math
A10: Legal recorded access to a public road ★ | B10: NOT STATED | C10: A gravel drive and a friendly neighbour are not access. Most common land killer.
A11: Perc / soils (where no public sewer) ★ | B11: NOT STATED | C11: No septic approval means no house means no retail buyer.
A12: Utilities AT the parcel + extension cost ★ | B12: NOT STATED | C12: 'In the area' is not at the parcel. Get the distance and who pays.
A13: FEMA flood zone / wetlands ★ | B13: NOT STATED | C13: Wetlands do not stop the purchase. They stop the building.
A14: Zoning + minimum lot size ★ | B14: NOT STATED | C14: Decides how many lots the acreage actually yields.
A15: Boundary / survey ★ | B15: NOT STATED | C15: Deeded acres are often not surveyed acres.
A16: Severed mineral / timber / water rights ★ | B16: NOT STATED | C16: A severed mineral owner may have surface entry rights.
A17: Back taxes, liens, special assessments ★ | B17: NOT STATED | C17: Often the reason it is cheap.
A18: Unresolved | B18: =COUNTIF(B10:B17,"NOT STATED") | C18: Type OK / NOT STATED / KILL in column B
A19: Kills | B19: =COUNTIF(B10:B17,"KILL")
A20: FILTER VERDICT | B20: =IFERROR(IF(B19>0,"KILLED — "&B19&" fatal item(s)",IF(B18>0,"PROCEED, BUT NAME THE "&B18&" UNRESOLVED IN THE VERDICT","All eight answered")),"—")
A22: 3. ACREAGE & VALUE — usable acres, never deeded
A23: Deeded acres ★
A24: Unusable acres (flood, wetland, ROW, unbuildable) ★
A25: USABLE ACRES | B25: =IFERROR(B23-B24,"—")
A26: Comp value $ per USABLE acre ★ | C26: Never blend comps across parcel-size classes without adjusting
A27: Indicated value | B27: =IFERROR(B25*B26,"—")
A28: Asking price ★
A29: $ per usable acre at the ask | B29: =IFERROR(B28/B25,"—")
A30: Ask as % of indicated value | B30: =IFERROR(B28/B27,"—")
A32: 4. CARRY — the whole expense model on any owned play
A33: Expected hold (months) ★ | C33: Near zero on a wholesale — do not manufacture a carry figure for play 1
A34: Property tax / yr ★
A35: Insurance / yr ★
A36: Mowing, assessments, other / yr ★
A37: Interest if financed / yr ★
A38: TOTAL CARRY OVER THE HOLD | B38: =IFERROR((B34+B35+B36+B37)*B33/12,"—")
A39: Ag / current-use recoupment exposure ★ | C39: CAUV, rollback taxes, Williamson Act — clawback on change of use
A40: Entitlement cost (play 4) ★
A41: Max carry months you can fund ★ | B41: 24
A42: CARRY CAPACITY | B42: =IFERROR(IF(B33>B41,"FAIL — hold exceeds what you can fund","OK"),"—")
A44: 5. ALL-IN COST
A45: Purchase price ★
...

Sheet Leasehold
A1: ZOXIRO — LEASEHOLD vs FEE SIMPLE
A2: A cap rate assumes the income never stops. On a leasehold it stops on a date. Run this whenever the interest is not fee simple.
A4: 1. WHAT ARE YOU ACTUALLY BUYING?
A5: Interest (1 = Fee simple, 2 = Leasehold) ★ | B5: 1
A6: Ground lease expiry date ★ | C6: From the CURRENT amendment — not the lease abstract, which is often years out of date
A7: Today | B7: =TODAY()
A8: YEARS REMAINING | B8: =IFERROR(IF(B5=2,YEARFRAC(B7,B6),"n/a — fee simple"),"—")
A9: Annual ground rent ★ | C9: Senior to every other claim on the property
A10: Rent reset / escalation mechanism ★ | C10: e.g. resets every 5 yrs to 80% of average total rent paid — ratchets up with YOUR success
A11: Residual to you at expiry ★ | B11: 0 | C11: Usually 0 — improvements revert. NEGATIVE if the lessor can require removal at your cost.
A13: 2. THE NUMBER THE BROKER QUOTES
A14: NOI after ground rent ★
A15: Asking price ★
A16: Quoted cap rate | B16: =IFERROR(B14/B15,"—")
A17: READ THIS | B17: =IFERROR(IF(B5=2,"NOT A CAP RATE. This treats a lease ending in "&TEXT(B8,"0.0")&" years as though it ran forever. Use section 3.","Fee simple — cap rate is valid."),"—")
A19: 3. WHAT A FINITE TERM ACTUALLY SUPPORTS
A20: Discount rate ★ | B20: 0.09 | C20: Carry the finite term, the vacancy, the counterparty and the building age in this number
A21: Annual NOI growth ★ | B21: 0.025 | C21: Net of the ground rent ratchet, not gross of it
A22: SUPPORTABLE VALUE | B22: =IFERROR(IF(B5<>2,"n/a — fee simple",B14*(1-((1+B21)/(1+B20))^B8)/(B20-B21)+B11/((1+B20)^B8)),"—")
A23: Gap vs the ask | B23: =IFERROR(IF(B5<>2,"n/a",B15-B22),"—")
A24: Ask as a multiple of supportable | B24: =IFERROR(IF(B5<>2,"n/a",B15/B22),"—")
A26: 4. SENSITIVITY — supportable value by discount rate
A27: at 8% | B27: =IFERROR(IF($B$5<>2,"n/a",$B$14*(1-((1+$B$21)/(1+0.08))^$B$8)/(0.08-$B$21)+$B$11/((1+0.08)^$B$8)),"—")
A28: at 9% | B28: =IFERROR(IF($B$5<>2,"n/a",$B$14*(1-((1+$B$21)/(1+0.09))^$B$8)/(0.09-$B$21)+$B$11/((1+0.09)^$B$8)),"—")
A29: at 10% | B29: =IFERROR(IF($B$5<>2,"n/a",$B$14*(1-((1+$B$21)/(1+0.1))^$B$8)/(0.1-$B$21)+$B$11/((1+0.1)^$B$8)),"—")
